Workbook
Name Slicer_Age_Group: #N/A
Name Slicer_Gender: #N/A
Name Slicer_Months: #N/A

Sheet Dashboard

Sheet Analysis
A3: Analysis
A4: From our data it is shown that Apex General Hospital has about 19% of the total population admitted into the hospital still in the hospital and yet to be discharged
A5: and about 98% of the patients are in Oncology department, and these patients have been in the hospital on an average of 725days since the day of admission.
A6: It can also be said from our data that about 39% of the Patients admitted are High Risk patient, that is to say they are discharged but still being followed up,
A7: and this patient are are from Neurology and Cardiology department, 98% of the patients discharged and are recovered are from emergency ward department,
A8: one patient each has been discharged and recovered from the remaining three department.
A13: ANSWERS
A14: 1. The department with the highest revenue is the Emergency Ward, the Emergency Ward made about 40% of the Total Revenue
A15: 2. The most busiest day in the hospital is on Saturday, for 190 patients out of 483 patients in total got admitted into the Hospital on Saturdays, compared to other days with a count of 2, 1, 93 etc.
A16: Another concern is that out of 86 Patients that are admitted into the Oncology department, only two patients are discharged, one on follow-up while one has fully recovered. The success rate is low
A17: 3. The management should meet with the Doctor in the Oncology department and ask for the reason why patients stay longer than required time in the ward, could it be that an assistant is needed to help speed
A18: up the activities in the ward or the ward is in need of some tools/equipment.

Sheet Pivot Table
A1: KPI Cards | F1: Charts Pivot Tables | M1: Slicers | X1: Charts for KPI Cards | AL1: CHARTS
F4: Number of Patient still Admitted
A5: Median Length of Stay | F5: Row Labels | G5: Count of Patient ID
A6: Median Length of Stay | F6: Patient Discharged | G6: 389 | H6: =GETPIVOTDATA("Patient ID",$F$5,"Admission Status","Still Admitted") -> 94 | I6: =GETPIVOTDATA("Patient ID",$F$5,"Admission Status","Still Admitted")/GETPIVOTDATA("Patient ID",$F$5) -> 0.19461698
A7: 8 | B7: =GETPIVOTDATA("Calculated Median",$A$6) -> 8 | F7: Still Admitted | G7: 94
F8: Grand Total | G8: 483
A10: Sum of Treatment Cost
A11: Sum of Treatment Cost
A12: 115382590 | B12: =GETPIVOTDATA("Treatment Cost",$A$11) -> 115382590
F13: Number of Patient Discharged
F14: Row Labels | G14: Count of Patient ID
A15: Number of High Risk Patient | F15: Patient Discharged | G15: 389 | H15: =GETPIVOTDATA("Patient ID",$F$14,"Admission Status","Patient Discharged") -> 389 | I15: =GETPIVOTDATA("Patient ID",$F$14,"Admission Status","Patient Discharged")/GETPIVOTDATA("Patient ID",$F$14) -> 0.80538302
A16: Row Labels | B16: Count of Readmission Risk | F16: Still Admitted | G16: 94
A17: High Risk Patient | B17: 192 | C17: =GETPIVOTDATA("Readmission Risk",$A$16,"Readmission Risk","High Risk Patient") -> 192 | F17: Grand Total | G17: 483
A18: Low Risk Patient | B18: 291
A19: Grand Total | B19: 483
F21: Revenue by Department
A22: Number of Department | F22: Row Labels | G22: Sum of Treatment Cost
A23: Row Labels | F23: Emergency Ward | G23: 46398860
A24: Cardiology | B24: =COUNTA(A24:A28) -> 5 | C24: =B24 -> 5 | F24: Neurology | G24: 23323000
A25: Emergency Ward | F25: Oncology | G25: 22712220
A26: Neurology | F26: Cardiology | G26: 22518510
A27: Oncology | F27: Pediatrics | G27: 430000
A28: Pediatrics | F28: Grand Total | G28: 115382590
A29: Grand Total
A32: Total Unique Patient | F32: Admission Trend by Weekday
A33: Row Labels | F33: Row Labels | G33: Count of Patient ID
A34: HOSP-101 | B34: =COUNTA(A34:A516) -> 483 | C34: =B34 -> 483 | F34: Mon | G34: 97
A35: HOSP-102 | F35: Tue | G35: 2
A36: HOSP-103 | F36: Wed | G36: 2
A37: HOSP-104 | F37: Thu | G37: 98
A38: HOSP-105 | F38: Fri | G38: 1
A39: HOSP-106 | F39: Sat | G39: 190
A40: HOSP-107 | F40: Sun | G40: 93
A41: HOSP-108 | F41: Grand Total | G41: 483
A42: HOSP-109
A43: HOSP-110
A44: HOSP-111
A45: HOSP-112
A46: HOSP-113
...

Sheet Wire Frame

Sheet Calculated Metrics
A1: Patient ID | B1: Admission Date | C1: Discharge Date | D1: Length of Stay | E1: Admission Status | F1: Admission Category | G1: Department | H1: Age | I1: Age Group | J1: Gender | K1: Treatment Cost | L1: Billing Category | M1: Outcome | N1: Readmission Risk | O1: Doctor | P1: Patient Type | Q1: Room Number | R1: Day | S1: Months | T1: Year | U1: Month and Year | V1: Calculated Median
A2: HOSP-101 | B2: 45322 | C2: 45322 | D2: =IF(ISBLANK(Table14[[#This Row],[Discharge Date]]),TODAY()-Table14[[#This Row],[Admission Date]], Table14[[#This Row],[Discharge Date]]-Table14[[#This Row],[Admission Date]]) -> 0 | E2: =IF(Table14[[#This Row],[Discharge Date]]="","Still Admitted","Patient Discharged") -> Patient Discharged | F2: =IF(WEEKDAY(Table14[[#This Row],[Admission Date]],2)>5,"Weekend","Weekday") -> Weekday | G2: Cardiology | H2: 67 | I2: {=_xlfn.IFS(Table14[[#This Row],[Age]]<18,"Children",Table14[[#This Row],[Age]]<50,"Adult",Table14[[#This Row],[Age]]>=50,"Elderly")} -> Elderly | J2: Male | K2: 8500 | L2: {=_xlfn.IFS(Table14[[#This Row],[Treatment Cost]]<50000,"Low Billing",Table14[[#This Row],[Treatment Cost]]<200000,"Moderate Billing",Table14[[#This Row],[Treatment Cost]]>=200000,"High Billing")} -> Low Billing | M2: Recovered | N2: =IF(AND(Table14[[#This Row],[Outcome]]="Follow-up",Table14[[#This Row],[Admission Status]]="Patient Discharged"),"High Risk Patient","Low Risk Patient") -> Low Risk Patient | O2: =IFERROR(VLOOKUP(Table14[[#This Row],[Department]],Doctor_Info!A:D,2,FALSE), "") -> Dr. Ada | P2: =IF(COUNTIF(A:A,Table14[[#This Row],[Patient ID]]>1),"Returning Patient","New Patient") -> New Patient | Q2: =_xlfn.XLOOKUP(Table14[[#This Row],[Department]], Doctor_Info!A:A, Doctor_Info!C:C, "")&"" -> 301 | R2: =TEXT(Table14[[#This Row],[Admission Date]],"ddd") -> Wed | S2: =TEXT(Table14[[#This Row],[Admission Date]],"mmm") -> Jan | T2: =TEXT(Table14[[#This Row],[Admission Date]],"yyyy") -> 2024 | U2: =TEXT(Table14[[#This Row],[Admission Date]],"mmm-yyyy") -> Jan-2024 | V2: =MEDIAN($D$2:$D$484) -> 8
A3: HOSP-102 | B3: 45293 | C3: 45294 | D3: =IF(ISBLANK(Table14[[#This Row],[Discharge Date]]),TODAY()-Table14[[#This Row],[Admission Date]], Table14[[#This Row],[Discharge Date]]-Table14[[#This Row],[Admission Date]]) -> 1 | E3: =IF(Table14[[#This Row],[Discharge Date]]="","Still Admitted","Patient Discharged") -> Patient Discharged | F3: =IF(WEEKDAY(Table14[[#This Row],[Admission Date]],2)>5,"Weekend","Weekday") -> Weekday | G3: Emergency Ward | H3: 22 | I3: {=_xlfn.IFS(Table14[[#This Row],[Age]]<18,"Children",Table14[[#This Row],[Age]]<50,"Adult",Table14[[#This Row],[Age]]>=50,"Elderly")} -> Adult | J3: Female | K3: 900 | L3: {=_xlfn.IFS(Table14[[#This Row],[Treatment Cost]]<50000,"Low Billing",Table14[[#This Row],[Treatment Cost]]<200000,"Moderate Billing",Table14[[#This Row],[Treatment Cost]]>=200000,"High Billing")} -> Low Billing | M3: Recovered | N3: =IF(AND(Table14[[#This Row],[Outcome]]="Follow-up",Table14[[#This Row],[Admission Status]]="Patient Discharged"),"High Risk Patient","Low Risk Patient") -> Low Risk Patient | O3: =IFERROR(VLOOKUP(Table14[[#This Row],[Department]],Doctor_Info!A:D,2,FALSE), "") -> Dr. Kofi | P3: =IF(COUNTIF(A:A,Table14[[#This Row],[Patient ID]]>1),"Returning Patient","New Patient") -> New Patient | Q3: =_xlfn.XLOOKUP(Table14[[#This Row],[Department]], Doctor_Info!A:A, Doctor_Info!C:C, "")&"" -> 102 | R3: =TEXT(Table14[[#This Row],[Admission Date]],"ddd") -> Tue | S3: =TEXT(Table14[[#This Row],[Admission Date]],"mmm") -> Jan | T3: =TEXT(Table14[[#This Row],[Admission Date]],"yyyy") -> 2024 | U3: =TEXT(Table14[[#This Row],[Admission Date]],"mmm-yyyy") -> Jan-2024 | V3: =MEDIAN($D$2:$D$484) -> 8
A4: HOSP-103 | B4: 45296 | C4: 45311 | D4: =IF(ISBLANK(Table14[[#This Row],[Discharge Date]]),TODAY()-Table14[[#This Row],[Admission Date]], Table14[[#This Row],[Discharge Date]]-Table14[[#This Row],[Admission Date]]) -> 15 | E4: =IF(Table14[[#This Row],[Discharge Date]]="","Still Admitted","Patient Discharged") -> Patient Discharged | F4: =IF(WEEKDAY(Table14[[#This Row],[Admission Date]],2)>5,"Weekend","Weekday") -> Weekday | G4: Oncology | H4: 54 | I4: {=_xlfn.IFS(Table14[[#This Row],[Age]]<18,"Children",Table14[[#This Row],[Age]]<50,"Adult",Table14[[#This Row],[Age]]>=50,"Elderly")} -> Elderly | J4: Female | K4: 15000 | L4: {=_xlfn.IFS(Table14[[#This Row],[Treatment Cost]]<50000,"Low Billing",Table14[[#This Row],[Treatment Cost]]<200000,"Moderate Billing",Table14[[#This Row],[Treatment Cost]]>=200000,"High Billing")} -> Low Billing | M4: Follow-up | N4: =IF(AND(Table14[[#This Row],[Outcome]]="Follow-up",Table14[[#This Row],[Admission Status]]="Patient Discharged"),"High Risk Patient","Low Risk Patient") -> High Risk Patient | O4: =IFERROR(VLOOKUP(Table14[[#This Row],[Department]],Doctor_Info!A:D,2,FALSE), "") -> Dr. George | P4: =IF(COUNTIF(A:A,Table14[[#This Row],[Patient ID]]>1),"Returning Patient","New Patient") -> New Patient | Q4: =_xlfn.XLOOKUP(Table14[[#This Row],[Department]], Doctor_Info!A:A, Doctor_Info!C:C, "")&"" -> 405 | R4: =TEXT(Table14[[#This Row],[Admission Date]],"ddd") -> Fri | S4: =TEXT(Table14[[#This Row],[Admission Date]],"mmm") -> Jan | T4: =TEXT(Table14[[#This Row],[Admission Date]],"yyyy") -> 2024 | U4: =TEXT(Table14[[#This Row],[Admission Date]],"mmm-yyyy") -> Jan-2024 | V4: =MEDIAN($D$2:$D$484) -> 8
A5: HOSP-104 | B5: 45301 | C5: 45303 | D5: =IF(ISBLANK(Table14[[#This Row],[Discharge Date]]),TODAY()-Table14[[#This Row],[Admission Date]], Table14[[#This Row],[Discharge Date]]-Table14[[#This Row],[Admission Date]]) -> 2 | E5: =IF(Table14[[#This Row],[Discharge Date]]="","Still Admitted","Patient Discharged") -> Patient Discharged | F5: =IF(WEEKDAY(Table14[[#This Row],[Admission Date]],2)>5,"Weekend","Weekday") -> Weekday | G5: Pediatrics | H5: 8 | I5: {=_xlfn.IFS(Table14[[#This Row],[Age]]<18,"Children",Table14[[#This Row],[Age]]<50,"Adult",Table14[[#This Row],[Age]]>=50,"Elderly")} -> Children | J5: Male | K5: 250000 | L5: {=_xlfn.IFS(Table14[[#This Row],[Treatment Cost]]<50000,"Low Billing",Table14[[#This Row],[Treatment Cost]]<200000,"Moderate Billing",Table14[[#This Row],[Treatment Cost]]>=200000,"High Billing")} -> High Billing | M5: Follow-up | N5: =IF(AND(Table14[[#This Row],[Outcome]]="Follow-up",Table14[[#This Row],[Admission Status]]="Patient Discharged"),"High Risk Patient","Low Risk Patient") -> High Risk Patient | O5: =IFERROR(VLOOKUP(Table14[[#This Row],[Department]],Doctor_Info!A:D,2,FALSE), "") -> Dr. Segun | P5: =IF(COUNTIF(A:A,Table14[[#This Row],[Patient ID]]>1),"Returning Patient","New Patient") -> New Patient | Q5: =_xlfn.XLOOKUP(Table14[[#This Row],[Department]], Doctor_Info!A:A, Doctor_Info!C:C, "")&"" -> 210 | R5: =TEXT(Table14[[#This Row],[Admission Date]],"ddd") -> Wed | S5: =TEXT(Table14[[#This Row],[Admission Date]],"mmm") -> Jan | T5: =TEXT(Table14[[#This Row],[Admission Date]],"yyyy") -> 2024 | U5: =TEXT(Table14[[#This Row],[Admission Date]],"mmm-yyyy") -> Jan-2024 | V5: =MEDIAN($D$2:$D$484) -> 8
A6: HOSP-105 | B6: 45321 | C6: 45322 | D6: =IF(ISBLANK(Table14[[#This Row],[Discharge Date]]),TODAY()-Table14[[#This Row],[Admission Date]], Table14[[#This Row],[Discharge Date]]-Table14[[#This Row],[Admission Date]]) -> 1 | E6: =IF(Table14[[#This Row],[Discharge Date]]="","Still Admitted","Patient Discharged") -> Patient Discharged | F6: =IF(WEEKDAY(Table14[[#This Row],[Admission Date]],2)>5,"Weekend","Weekday") -> Weekday | G6: Emergency Ward | H6: 31 | I6: {=_xlfn.IFS(Table14[[#This Row],[Age]]<18,"Children",Table14[[#This Row],[Age]]<50,"Adult",Table14[[#This Row],[Age]]>=50,"Elderly")} -> Adult | J6: Male | K6: 1100 | L6: {=_xlfn.IFS(Table14[[#This Row],[Treatment Cost]]<50000,"Low Billing",Table14[[#This Row],[Treatment Cost]]<200000,"Moderate Billing",Table14[[#This Row],[Treatment Cost]]>=200000,"High Billing")} -> Low Billing | M6: Recovered | N6: =IF(AND(Table14[[#This Row],[Outcome]]="Follow-up",Table14[[#This Row],[Admission Status]]="Patient Discharged"),"High Risk Patient","Low Risk Patient") -> Low Risk Patient | O6: =IFERROR(VLOOKUP(Table14[[#This Row],[Department]],Doctor_Info!A:D,2,FALSE), "") -> Dr. Kofi | P6: =IF(COUNTIF(A:A,Table14[[#This Row],[Patient ID]]>1),"Returning Patient","New Patient") -> New Patient | Q6: =_xlfn.XLOOKUP(Table14[[#This Row],[Department]], Doctor_Info!A:A, Doctor_Info!C:C, "")&"" -> 102 | R6: =TEXT(Table14[[#This Row],[Admission Date]],"ddd") -> Tue | S6: =TEXT(Table14[[#This Row],[Admission Date]],"mmm") -> Jan | T6: =TEXT(Table14[[#This Row],[Admission Date]],"yyyy") -> 2024 | U6: =TEXT(Table14[[#This Row],[Admission Date]],"mmm-yyyy") -> Jan-2024 | V6: =MEDIAN($D$2:$D$484) -> 8
A7: HOSP-106 | B7: 45306 | C7: 45313 | D7: =IF(ISBLANK(Table14[[#This Row],[Discharge Date]]),TODAY()-Table14[[#This Row],[Admission Date]], Table14[[#This Row],[Discharge Date]]-Table14[[#This Row],[Admission Date]]) -> 7 | E7: =IF(Table14[[#This Row],[Discharge Date]]="","Still Admitted","Patient Discharged") -> Patient Discharged | F7: =IF(WEEKDAY(Table14[[#This Row],[Admission Date]],2)>5,"Weekend","Weekday") -> Weekday | G7: Cardiology | H7: 72 | I7: {=_xlfn.IFS(Table14[[#This Row],[Age]]<18,"Children",Table14[[#This Row],[Age]]<50,"Adult",Table14[[#This Row],[Age]]>=50,"Elderly")} -> Elderly | J7: Female | K7: 9200 | L7: {=_xlfn.IFS(Table14[[#This Row],[Treatment Cost]]<50000,"Low Billing",Table14[[#This Row],[Treatment Cost]]<200000,"Moderate Billing",Table14[[#This Row],[Treatment Cost]]>=200000,"High Billing")} -> Low Billing | M7: Follow-up | N7: =IF(AND(Table14[[#This Row],[Outcome]]="Follow-up",Table14[[#This Row],[Admission Status]]="Patient Discharged"),"High Risk Patient","Low Risk Patient") -> High Risk Patient | O7: =IFERROR(VLOOKUP(Table14[[#This Row],[Department]],Doctor_Info!A:D,2,FALSE), "") -> Dr. Ada | P7: =IF(COUNTIF(A:A,Table14[[#This Row],[Patient ID]]>1),"Returning Patient","New Patient") -> New Patient | Q7: =_xlfn.XLOOKUP(Table14[[#This Row],[Department]], Doctor_Info!A:A, Doctor_Info!C:C, "")&"" -> 301 | R7: =TEXT(Table14[[#This Row],[Admission Date]],"ddd") -> Mon | S7: =TEXT(Table14[[#This Row],[Admission Date]],"mmm") -> Jan | T7: =TEXT(Table14[[#This Row],[Admission Date]],"yyyy") -> 2024 | U7: =TEXT(Table14[[#This Row],[Admission Date]],"mmm-yyyy") -> Jan-2024 | V7: =MEDIAN($D$2:$D$484) -> 8
A8: HOSP-107 | B8: 45309 | D8: =IF(ISBLANK(Table14[[#This Row],[Discharge Date]]),TODAY()-Table14[[#This Row],[Admission Date]], Table14[[#This Row],[Discharge Date]]-Table14[[#This Row],[Admission Date]]) -> 829 | E8: =IF(Table14[[#This Row],[Discharge Date]]="","Still Admitted","Patient Discharged") -> Still Admitted | F8: =IF(WEEKDAY(Table14[[#This Row],[Admission Date]],2)>5,"Weekend","Weekday") -> Weekday | G8: Neurology | H8: 41 | I8: {=_xlfn.IFS(Table14[[#This Row],[Age]]<18,"Children",Table14[[#This Row],[Age]]<50,"Adult",Table14[[#This Row],[Age]]>=50,"Elderly")} -> Adult | J8: Male | K8: 4500 | L8: {=_xlfn.IFS(Table14[[#This Row],[Treatment Cost]]<50000,"Low Billing",Table14[[#This Row],[Treatment Cost]]<200000,"Moderate Billing",Table14[[#This Row],[Treatment Cost]]>=200000,"High Billing")} -> Low Billing | M8: Pending | N8: =IF(AND(Table14[[#This Row],[Outcome]]="Follow-up",Table14[[#This Row],[Admission Status]]="Patient Discharged"),"High Risk Patient","Low Risk Patient") -> Low Risk Patient | O8: =IFERROR(VLOOKUP(Table14[[#This Row],[Department]],Doctor_Info!A:D,2,FALSE), "") -> Dr. Temi | P8: =IF(COUNTIF(A:A,Table14[[#This Row],[Patient ID]]>1),"Returning Patient","New Patient") -> New Patient | Q8: =_xlfn.XLOOKUP(Table14[[#This Row],[Department]], Doctor_Info!A:A, Doctor_Info!C:C, "")&"" -> 502 | R8: =TEXT(Table14[[#This Row],[Admission Date]],"ddd") -> Thu | S8: =TEXT(Table14[[#This Row],[Admission Date]],"mmm") -> Jan | T8: =TEXT(Table14[[#This Row],[Admission Date]],"yyyy") -> 2024 | U8: =TEXT(Table14[[#This Row],[Admission Date]],"mmm-yyyy") -> Jan-2024 | V8: =MEDIAN($D$2:$D$484) -> 8
A9: HOSP-108 | B9: 45311 | C9: 45321 | D9: =IF(ISBLANK(Table14[[#This Row],[Discharge Date]]),TODAY()-Table14[[#This Row],[Admission Date]], Table14[[#This Row],[Discharge Date]]-Table14[[#This Row],[Admission Date]]) -> 10 | E9: =IF(Table14[[#This Row],[Discharge Date]]="","Still Admitted","Patient Discharged") -> Patient Discharged | F9: =IF(WEEKDAY(Table14[[#This Row],[Admission Date]],2)>5,"Weekend","Weekday") -> Weekend | G9: Oncology | H9: 61 | I9: {=_xlfn.IFS(Table14[[#This Row],[Age]]<18,"Children",Table14[[#This Row],[Age]]<50,"Adult",Table14[[#This Row],[Age]]>=50,"Elderly")} -> Elderly | J9: Female | K9: 14000 | L9: {=_xlfn.IFS(Table14[[#This Row],[Treatment Cost]]<50000,"Low Billing",Table14[[#This Row],[Treatment Cost]]<200000,"Moderate Billing",Table14[[#This Row],[Treatment Cost]]>=200000,"High Billing")} -> Low Billing | M9: Recovered | N9: =IF(AND(Table14[[#This Row],[Outcome]]="Follow-up",Table14[[#This Row],[Admission Status]]="Patient Discharged"),"High Risk Patient","Low Risk Patient") -> Low Risk Patient | O9: =IFERROR(VLOOKUP(Table14[[#This Row],[Department]],Doctor_Info!A:D,2,FALSE), "") -> Dr. George | P9: =IF(COUNTIF(A:A,Table14[[#This Row],[Patient ID]]>1),"Returning Patient","New Patient") -> New Patient | Q9: =_xlfn.XLOOKUP(Table14[[#This Row],[Department]], Doctor_Info!A:A, Doctor_Info!C:C, "")&"" -> 405 | R9: =TEXT(Table14[[#This Row],[Admission Date]],"ddd") -> Sat | S9: =TEXT(Table14[[#This Row],[Admission Date]],"mmm") -> Jan | T9: =TEXT(Table14[[#This Row],[Admission Date]],"yyyy") -> 2024 | U9: =TEXT(Table14[[#This Row],[Admission Date]],"mmm-yyyy") -> Jan-2024 | V9: =MEDIAN($D$2:$D$484) -> 8
A10: HOSP-109 | B10: 45313 | C10: 45314 | D10: =IF(ISBLANK(Table14[[#This Row],[Discharge Date]]),TODAY()-Table14[[#This Row],[Admission Date]], Table14[[#This Row],[Discharge Date]]-Table14[[#This Row],[Admission Date]]) -> 1 | E10: =IF(Table14[[#This Row],[Discharge Date]]="","Still Admitted","Patient Discharged") -> Patient Discharged | F10: =IF(WEEKDAY(Table14[[#This Row],[Admission Date]],2)>5,"Weekend","Weekday") -> Weekday | G10: Emergency Ward | H10: 19 | I10: {=_xlfn.IFS(Table14[[#This Row],[Age]]<18,"Children",Table14[[#This Row],[Age]]<50,"Adult",Table14[[#This Row],[Age]]>=50,"Elderly")} -> Adult | J10: Male | K10: 850 | L10: {=_xlfn.IFS(Table14[[#This Row],[Treatment Cost]]<50000,"Low Billing",Table14[[#This Row],[Treatment Cost]]<200000,"Moderate Billing",Table14[[#This Row],[Treatment Cost]]>=200000,"High Billing")} -> Low Billing | M10: Recovered | N10: =IF(AND(Table14[[#This Row],[Outcome]]="Follow-up",Table14[[#This Row],[Admission Status]]="Patient Discharged"),"High Risk Patient","Low Risk Patient") -> Low Risk Patient | O10: =IFERROR(VLOOKUP(Table14[[#This Row],[Department]],Doctor_Info!A:D,2,FALSE), "") -> Dr. Kofi | P10: =IF(COUNTIF(A:A,Table14[[#This Row],[Patient ID]]>1),"Returning Patient","New Patient") -> New Patient | Q10: =_xlfn.XLOOKUP(Table14[[#This Row],[Department]], Doctor_Info!A:A, Doctor_Info!C:C, "")&"" -> 102 | R10: =TEXT(Table14[[#This Row],[Admission Date]],"ddd") -> Mon | S10: =TEXT(Table14[[#This Row],[Admission Date]],"mmm") -> Jan | T10: =TEXT(Table14[[#This Row],[Admission Date]],"yyyy") -> 2024 | U10: =TEXT(Table14[[#This Row],[Admission Date]],"mmm-yyyy") -> Jan-2024 | V10: =MEDIAN($D$2:$D$484) -> 8
A11: HOSP-110 | B11: 45316 | C11: 45319 | D11: =IF(ISBLANK(Table14[[#This Row],[Discharge Date]]),TODAY()-Table14[[#This Row],[Admission Date]], Table14[[#This Row],[Discharge Date]]-Table14[[#This Row],[Admission Date]]) -> 3 | E11: =IF(Table14[[#This Row],[Discharge Date]]="","Still Admitted","Patient Discharged") -> Patient Discharged | F11: =IF(WEEKDAY(Table14[[#This Row],[Admission Date]],2)>5,"Weekend","Weekday") -> Weekday | G11: Pediatrics | H11: 4 | I11: {=_xlfn.IFS(Table14[[#This Row],[Age]]<18,"Children",Table14[[#This Row],[Age]]<50,"Adult",Table14[[#This Row],[Age]]>=50,"Elderly")} -> Children | J11: Female | K11: 180000 | L11: {=_xlfn.IFS(Table14[[#This Row],[Treatment Cost]]<50000,"Low Billing",Table14[[#This Row],[Treatment Cost]]<200000,"Moderate Billing",Table14[[#This Row],[Treatment Cost]]>=200000,"High Billing")} -> Moderate Billing | M11: Recovered | N11: =IF(AND(Table14[[#This Row],[Outcome]]="Follow-up",Table14[[#This Row],[Admission Status]]="Patient Discharged"),"High Risk Patient","Low Risk Patient") -> Low Risk Patient | O11: =IFERROR(VLOOKUP(Table14[[#This Row],[Department]],Doctor_Info!A:D,2,FALSE), "") -> Dr. Segun | P11: =IF(COUNTIF(A:A,Table14[[#This Row],[Patient ID]]>1),"Returning Patient","New Patient") -> New Patient | Q11: =_xlfn.XLOOKUP(Table14[[#This Row],[Department]], Doctor_Info!A:A, Doctor_Info!C:C, "")&"" -> 210 | R11: =TEXT(Table14[[#This Row],[Admission Date]],"ddd") -> Thu | S11: =TEXT(Table14[[#This Row],[Admission Date]],"mmm") -> Jan | T11: =TEXT(Table14[[#This Row],[Admission Date]],"yyyy") -> 2024 | U11: =TEXT(Table14[[#This Row],[Admission Date]],"mmm-yyyy") -> Jan-2024 | V11: =MEDIAN($D$2:$D$484) -> 8
A12: HOSP-111 | B12: 45319 | C12: 45327 | D12: =IF(ISBLANK(Table14[[#This Row],[Discharge Date]]),TODAY()-Table14[[#This Row],[Admission Date]], Table14[[#This Row],[Discharge Date]]-Table14[[#This Row],[Admission Date]]) -> 8 | E12: =IF(Table14[[#This Row],[Discharge Date]]="","Still Admitted","Patient Discharged") -> Patient Discharged | F12: =IF(WEEKDAY(Table14[[#This Row],[Admission Date]],2)>5,"Weekend","Weekday") -> Weekend | G12: Cardiology | H12: 55 | I12: {=_xlfn.IFS(Table14[[#This Row],[Age]]<18,"Children",Table14[[#This Row],[Age]]<50,"Adult",Table14[[#This Row],[Age]]>=50,"Elderly")} -> Elderly | J12: Male | K12: 7600 | L12: {=_xlfn.IFS(Table14[[#This Row],[Treatment Cost]]<50000,"Low Billing",Table14[[#This Row],[Treatment Cost]]<200000,"Moderate Billing",Table14[[#This Row],[Treatment Cost]]>=200000,"High Billing")} -> Low Billing | M12: Follow-up | N12: =IF(AND(Table14[[#This Row],[Outcome]]="Follow-up",Table14[[#This Row],[Admission Status]]="Patient Discharged"),"High Risk Patient","Low Risk Patient") -> High Risk Patient | O12: =IFERROR(VLOOKUP(Table14[[#This Row],[Department]],Doctor_Info!A:D,2,FALSE), "") -> Dr. Ada | P12: =IF(COUNTIF(A:A,Table14[[#This Row],[Patient ID]]>1),"Returning Patient","New Patient") -> New Patient | Q12: =_xlfn.XLOOKUP(Table14[[#This Row],[Department]], Doctor_Info!A:A, Doctor_Info!C:C, "")&"" -> 301 | R12: =TEXT(Table14[[#This Row],[Admission Date]],"ddd") -> Sun | S12: =TEXT(Table14[[#This Row],[Admission Date]],"mmm") -> Jan | T12: =TEXT(Table14[[#This Row],[Admission Date]],"yyyy") -> 2024 | U12: =TEXT(Table14[[#This Row],[Admission Date]],"mmm-yyyy") -> Jan-2024 | V12: =MEDIAN($D$2:$D$484) -> 8
A13: HOSP-112 | B13: 45323 | C13: 45324 | D13: =IF(ISBLANK(Table14[[#This Row],[Discharge Date]]),TODAY()-Table14[[#This Row],[Admission Date]], Table14[[#This Row],[Discharge Date]]-Table14[[#This Row],[Admission Date]]) -> 1 | E13: =IF(Table14[[#This Row],[Discharge Date]]="","Still Admitted","Patient Discharged") -> Patient Discharged | F13: =IF(WEEKDAY(Table14[[#This Row],[Admission Date]],2)>5,"Weekend","Weekday") -> Weekday | G13: Emergency Ward | H13: 33 | I13: {=_xlfn.IFS(Table14[[#This Row],[Age]]<18,"Children",Table14[[#This Row],[Age]]<50,"Adult",Table14[[#This Row],[Age]]>=50,"Elderly")} -> Adult | J13: Female | K13: 1050 | L13: {=_xlfn.IFS(Table14[[#This Row],[Treatment Cost]]<50000,"Low Billing",Table14[[#This Row],[Treatment Cost]]<200000,"Moderate Billing",Table14[[#This Row],[Treatment Cost]]>=200000,"High Billing")} -> Low Billing | M13: Recovered | N13: =IF(AND(Table14[[#This Row],[Outcome]]="Follow-up",Table14[[#This Row],[Admission Status]]="Patient Discharged"),"High Risk Patient","Low Risk Patient") -> Low Risk Patient | O13: =IFERROR(VLOOKUP(Table14[[#This Row],[Department]],Doctor_Info!A:D,2,FALSE), "") -> Dr. Kofi | P13: =IF(COUNTIF(A:A,Table14[[#This Row],[Patient ID]]>1),"Returning Patient","New Patient") -> New Patient | Q13: =_xlfn.XLOOKUP(Table14[[#This Row],[Department]], Doctor_Info!A:A, Doctor_Info!C:C, "")&"" -> 102 | R13: =TEXT(Table14[[#This Row],[Admission Date]],"ddd") -> Thu | S13: =TEXT(Table14[[#This Row],[Admission Date]],"mmm") -> Feb | T13: =TEXT(Table14[[#This Row],[Admission Date]],"yyyy") -> 2024 | U13: =TEXT(Table14[[#This Row],[Admission Date]],"mmm-yyyy") -> Feb-2024 | V13: =MEDIAN($D$2:$D$484) -> 8
A14: HOSP-113 | B14: 45325 | C14: 45337 | D14: =IF(ISBLANK(Table14[[#This Row],[Discharge Date]]),TODAY()-Table14[[#This Row],[Admission Date]], Table14[[#This Row],[Discharge Date]]-Table14[[#This Row],[Admission Date]]) -> 12 | E14: =IF(Table14[[#This Row],[Discharge Date]]="","Still Admitted","Patient Discharged") -> Patient Discharged | F14: =IF(WEEKDAY(Table14[[#This Row],[Admission Date]],2)>5,"Weekend","Weekday") -> Weekend | G14: Neurology | H14: 68 | I14: {=_xlfn.IFS(Table14[[#This Row],[Age]]<18,"Children",Table14[[#This Row],[Age]]<50,"Adult",Table14[[#This Row],[Age]]>=50,"Elderly")} -> Elderly | J14: Male | K14: 11000 | L14: {=_xlfn.IFS(Table14[[#This Row],[Treatment Cost]]<50000,"Low Billing",Table14[[#This Row],[Treatment Cost]]<200000,"Moderate Billing",Table14[[#This Row],[Treatment Cost]]>=200000,"High Billing")} -> Low Billing | M14: Follow-up | N14: =IF(AND(Table14[[#This Row],[Outcome]]="Follow-up",Table14[[#This Row],[Admission Status]]="Patient Discharged"),"High Risk Patient","Low Risk Patient") -> High Risk Patient | O14: =IFERROR(VLOOKUP(Table14[[#This Row],[Department]],Doctor_Info!A:D,2,FALSE), "") -> Dr. Temi | P14: =IF(COUNTIF(A:A,Table14[[#This Row],[Patient ID]]>1),"Returning Patient","New Patient") -> New Patient | Q14: =_xlfn.XLOOKUP(Table14[[#This Row],[Department]], Doctor_Info!A:A, Doctor_Info!C:C, "")&"" -> 502 | R14: =TEXT(Table14[[#This Row],[Admission Date]],"ddd") -> Sat | S14: =TEXT(Table14[[#This Row],[Admission Date]],"mmm") -> Feb | T14: =TEXT(Table14[[#This Row],[Admission Date]],"yyyy") -> 2024 | U14: =TEXT(Table14[[#This Row],[Admission Date]],"mmm-yyyy") -> Feb-2024 | V14: =MEDIAN($D$2:$D$484) -> 8
A15: HOSP-114 | B15: 45327 | C15: 45328 | D15: =IF(ISBLANK(Table14[[#This Row],[Discharge Date]]),TODAY()-Table14[[#This Row],[Admission Date]], Table14[[#This Row],[Discharge Date]]-Table14[[#This Row],[Admission Date]]) -> 1 | E15: =IF(Table14[[#This Row],[Discharge Date]]="","Still Admitted","Patient Discharged") -> Patient Discharged | F15: =IF(WEEKDAY(Table14[[#This Row],[Admission Date]],2)>5,"Weekend","Weekday") -> Weekday | G15: Emergency Ward | H15: 25 | I15: {=_xlfn.IFS(Table14[[#This Row],[Age]]<18,"Children",Table14[[#This Row],[Age]]<50,"Adult",Table14[[#This Row],[Age]]>=50,"Elderly")} -> Adult | J15: Female | K15: 950 | L15: {=_xlfn.IFS(Table14[[#This Row],[Treatment Cost]]<50000,"Low Billing",Table14[[#This Row],[Treatment Cost]]<200000,"Moderate Billing",Table14[[#This Row],[Treatment Cost]]>=200000,"High Billing")} -> Low Billing | M15: Recovered | N15: =IF(AND(Table14[[#This Row],[Outcome]]="Follow-up",Table14[[#This Row],[Admission Status]]="Patient Discharged"),"High Risk Patient","Low Risk Patient") -> Low Risk Patient | O15: =IFERROR(VLOOKUP(Table14[[#This Row],[Department]],Doctor_Info!A:D,2,FALSE), "") -> Dr. Kofi | P15: =IF(COUNTIF(A:A,Table14[[#This Row],[Patient ID]]>1),"Returning Patient","New Patient") -> New Patient | Q15: =_xlfn.XLOOKUP(Table14[[#This Row],[Department]], Doctor_Info!A:A, Doctor_Info!C:C, "")&"" -> 102 | R15: =TEXT(Table14[[#This Row],[Admission Date]],"ddd") -> Mon | S15: =TEXT(Table14[[#This Row],[Admission Date]],"mmm") -> Feb | T15: =TEXT(Table14[[#This Row],[Admission Date]],"yyyy") -> 2024 | U15: =TEXT(Table14[[#This Row],[Admission Date]],"mmm-yyyy") -> Feb-2024 | V15: =MEDIAN($D$2:$D$484) -> 8
A16: HOSP-115 | B16: 45332 | D16: =IF(ISBLANK(Table14[[#This Row],[Discharge Date]]),TODAY()-Table14[[#This Row],[Admission Date]], Table14[[#This Row],[Discharge Date]]-Table14[[#This Row],[Admission Date]]) -> 806 | E16: =IF(Table14[[#This Row],[Discharge Date]]="","Still Admitted","Patient Discharged") -> Still Admitted | F16: =IF(WEEKDAY(Table14[[#This Row],[Admission Date]],2)>5,"Weekend","Weekday") -> Weekend | G16: Oncology | H16: 49 | I16: {=_xlfn.IFS(Table14[[#This Row],[Age]]<18,"Children",Table14[[#This Row],[Age]]<50,"Adult",Table14[[#This Row],[Age]]>=50,"Elderly")} -> Adult | J16: Female | K16: 12500 | L16: {=_xlfn.IFS(Table14[[#This Row],[Treatment Cost]]<50000,"Low Billing",Table14[[#This Row],[Treatment Cost]]<200000,"Moderate Billing",Table14[[#This Row],[Treatment Cost]]>=200000,"High Billing")} -> Low Billing | M16: Pending | N16: =IF(AND(Table14[[#This Row],[Outcome]]="Follow-up",Table14[[#This Row],[Admission Status]]="Patient Discharged"),"High Risk Patient","Low Risk Patient") -> Low Risk Patient | O16: =IFERROR(VLOOKUP(Table14[[#This Row],[Department]],Doctor_Info!A:D,2,FALSE), "") -> Dr. George | P16: =IF(COUNTIF(A:A,Table14[[#This Row],[Patient ID]]>1),"Returning Patient","New Patient") -> New Patient | Q16: =_xlfn.XLOOKUP(Table14[[#This Row],[Department]], Doctor_Info!A:A, Doctor_Info!C:C, "")&"" -> 405 | R16: =TEXT(Table14[[#This Row],[Admission Date]],"ddd") -> Sat | S16: =TEXT(Table14[[#This Row],[Admission Date]],"mmm") -> Feb | T16: =TEXT(Table14[[#This Row],[Admission Date]],"yyyy") -> 2024 | U16: =TEXT(Table14[[#This Row],[Admission Date]],"mmm-yyyy") -> Feb-2024 | V16: =MEDIAN($D$2:$D$484) -> 8
A17: HOSP-116 | B17: 45319 | C17: 45327 | D17: =IF(ISBLANK(Table14[[#This Row],[Discharge Date]]),TODAY()-Table14[[#This Row],[Admission Date]], Table14[[#This Row],[Discharge Date]]-Table14[[#This Row],[Admission Date]]) -> 8 | E17: =IF(Table14[[#This Row],[Discharge Date]]="","Still Admitted","Patient Discharged") -> Patient Discharged | F17: =IF(WEEKDAY(Table14[[#This Row],[Admission Date]],2)>5,"Weekend","Weekday") -> Weekend | G17: Cardiology | H17: 40 | I17: {=_xlfn.IFS(Table14[[#This Row],[Age]]<18,"Children",Table14[[#This Row],[Age]]<50,"Adult",Table14[[#This Row],[Age]]>=50,"Elderly")} -> Adult | J17: Male | K17: 9530 | L17: {=_xlfn.IFS(Table14[[#This Row],[Treatment Cost]]<50000,"Low Billing",Table14[[#This Row],[Treatment Cost]]<200000,"Moderate Billing",Table14[[#This Row],[Treatment Cost]]>=200000,"High Billing")} -> Low Billing | M17: Follow-up | N17: =IF(AND(Table14[[#This Row],[Outcome]]="Follow-up",Table14[[#This Row],[Admission Status]]="Patient Discharged"),"High Risk Patient","Low Risk Patient") -> High Risk Patient | O17: =IFERROR(VLOOKUP(Table14[[#This Row],[Department]],Doctor_Info!A:D,2,FALSE), "") -> Dr. Ada | P17: =IF(COUNTIF(A:A,Table14[[#This Row],[Patient ID]]>1),"Returning Patient","New Patient") -> New Patient | Q17: =_xlfn.XLOOKUP(Table14[[#This Row],[Department]], Doctor_Info!A:A, Doctor_Info!C:C, "")&"" -> 301 | R17: =TEXT(Table14[[#This Row],[Admission Date]],"ddd") -> Sun | S17: =TEXT(Table14[[#This Row],[Admission Date]],"mmm") -> Jan | T17: =TEXT(Table14[[#This Row],[Admission Date]],"yyyy") -> 2024 | U17: =TEXT(Table14[[#This Row],[Admission Date]],"mmm-yyyy") -> Jan-2024 | V17: =MEDIAN($D$2:$D$484) -> 8
A18: HOSP-117 | B18: 45323 | C18: 45324 | D18: =IF(ISBLANK(Table14[[#This Row],[Discharge Date]]),TODAY()-Table14[[#This Row],[Admission Date]], Table14[[#This Row],[Discharge Date]]-Table14[[#This Row],[Admission Date]]) -> 1 | E18: =IF(Table14[[#This Row],[Discharge Date]]="","Still Admitted","Patient Discharged") -> Patient Discharged | F18: =IF(WEEKDAY(Table14[[#This Row],[Admission Date]],2)>5,"Weekend","Weekday") -> Weekday | G18: Emergency Ward | H18: 38 | I18: {=_xlfn.IFS(Table14[[#This Row],[Age]]<18,"Children",Table14[[#This Row],[Age]]<50,"Adult",Table14[[#This Row],[Age]]>=50,"Elderly")} -> Adult | J18: Female | K18: 10500 | L18: {=_xlfn.IFS(Table14[[#This Row],[Treatment Cost]]<50000,"Low Billing",Table14[[#This Row],[Treatment Cost]]<200000,"Moderate Billing",Table14[[#This Row],[Treatment Cost]]>=200000,"High Billing")} -> Low Billing | M18: Recovered | N18: =IF(AND(Table14[[#This Row],[Outcome]]="Follow-up",Table14[[#This Row],[Admission Status]]="Patient Discharged"),"High Risk Patient","Low Risk Patient") -> Low Risk Patient | O18: =IFERROR(VLOOKUP(Table14[[#This Row],[Department]],Doctor_Info!A:D,2,FALSE), "") -> Dr. Kofi | P18: =IF(COUNTIF(A:A,Table14[[#This Row],[Patient ID]]>1),"Returning Patient","New Patient") -> New Patient | Q18: =_xlfn.XLOOKUP(Table14[[#This Row],[Department]], Doctor_Info!A:A, Doctor_Info!C:C, "")&"" -> 102 | R18: =TEXT(Table14[[#This Row],[Admission Date]],"ddd") -> Thu | S18: =TEXT(Table14[[#This Row],[Admission Date]],"mmm") -> Feb | T18: =TEXT(Table14[[#This Row],[Admission Date]],"yyyy") -> 2024 | U18: =TEXT(Table14[[#This Row],[Admission Date]],"mmm-yyyy") -> Feb-2024 | V18: =MEDIAN($D$2:$D$484) -> 8
A19: HOSP-118 | B19: 45325 | C19: 45337 | D19: =IF(ISBLANK(Table14[[#This Row],[Discharge Date]]),TODAY()-Table14[[#This Row],[Admission Date]], Table14[[#This Row],[Discharge Date]]-Table14[[#This Row],[Admission Date]]) -> 12 | E19: =IF(Table14[[#This Row],[Discharge Date]]="","Still Admitted","Patient Discharged") -> Patient Discharged | F19: =IF(WEEKDAY(Table14[[#This Row],[Admission Date]],2)>5,"Weekend","Weekday") -> Weekend | G19: Neurology | H19: 36 | I19: {=_xlfn.IFS(Table14[[#This Row],[Age]]<18,"Children",Table14[[#This Row],[Age]]<50,"Adult",Table14[[#This Row],[Age]]>=50,"Elderly")} -> Adult | J19: Male | K19: 11470 | L19: {=_xlfn.IFS(Table14[[#This Row],[Treatment Cost]]<50000,"Low Billing",Table14[[#This Row],[Treatment Cost]]<200000,"Moderate Billing",Table14[[#This Row],[Treatment Cost]]>=200000,"High Billing")} -> Low Billing | M19: Follow-up | N19: =IF(AND(Table14[[#This Row],[Outcome]]="Follow-up",Table14[[#This Row],[Admission Status]]="Patient Discharged"),"High Risk Patient","Low Risk Patient") -> High Risk Patient | O19: =IFERROR(VLOOKUP(Table14[[#This Row],[Department]],Doctor_Info!A:D,2,FALSE), "") -> Dr. Temi | P19: =IF(COUNTIF(A:A,Table14[[#This Row],[Patient ID]]>1),"Returning Patient","New Patient") -> New Patient | Q19: =_xlfn.XLOOKUP(Table14[[#This Row],[Department]], Doctor_Info!A:A, Doctor_Info!C:C, "")&"" -> 502 | R19: =TEXT(Table14[[#This Row],[Admission Date]],"ddd") -> Sat | S19: =TEXT(Table14[[#This Row],[Admission Date]],"mmm") -> Feb | T19: =TEXT(Table14[[#This Row],[Admission Date]],"yyyy") -> 2024 | U19: =TEXT(Table14[[#This Row],[Admission Date]],"mmm-yyyy") -> Feb-2024 | V19: =MEDIAN($D$2:$D$484) -> 8
A20: HOSP-119 | B20: 45327 | C20: 45328 | D20: =IF(ISBLANK(Table14[[#This Row],[Discharge Date]]),TODAY()-Table14[[#This Row],[Admission Date]], Table14[[#This Row],[Discharge Date]]-Table14[[#This Row],[Admission Date]]) -> 1 | E20: =IF(Table14[[#This Row],[Discharge Date]]="","Still Admitted","Patient Discharged") -> Patient Discharged | F20: =IF(WEEKDAY(Table14[[#This Row],[Admission Date]],2)>5,"Weekend","Weekday") -> Weekday | G20: Emergency Ward | H20: 34 | I20: {=_xlfn.IFS(Table14[[#This Row],[Age]]<18,"Children",Table14[[#This Row],[Age]]<50,"Adult",Table14[[#This Row],[Age]]>=50,"Elderly")} -> Adult | J20: Female | K20: 12440 | L20: {=_xlfn.IFS(Table14[[#This Row],[Treatment Cost]]<50000,"Low Billing",Table14[[#This Row],[Treatment Cost]]<200000,"Moderate Billing",Table14[[#This Row],[Treatment Cost]]>=200000,"High Billing")} -> Low Billing | M20: Recovered | N20: =IF(AND(Table14[[#This Row],[Outcome]]="Follow-up",Table14[[#This Row],[Admission Status]]="Patient Discharged"),"High Risk Patient","Low Risk Patient") -> Low Risk Patient | O20: =IFERROR(VLOOKUP(Table14[[#This Row],[Department]],Doctor_Info!A:D,2,FALSE), "") -> Dr. Kofi | P20: =IF(COUNTIF(A:A,Table14[[#This Row],[Patient ID]]>1),"Returning Patient","New Patient") -> New Patient | Q20: =_xlfn.XLOOKUP(Table14[[#This Row],[Department]], Doctor_Info!A:A, Doctor_Info!C:C, "")&"" -> 102 | R20: =TEXT(Table14[[#This Row],[Admission Date]],"ddd") -> Mon | S20: =TEXT(Table14[[#This Row],[Admission Date]],"mmm") -> Feb | T20: =TEXT(Table14[[#This Row],[Admission Date]],"yyyy") -> 2024 | U20: =TEXT(Table14[[#This Row],[Admission Date]],"mmm-yyyy") -> Feb-2024 | V20: =MEDIAN($D$2:$D$484) -> 8
A21: HOSP-120 | B21: 45332 | D21: =IF(ISBLANK(Table14[[#This Row],[Discharge Date]]),TODAY()-Table14[[#This Row],[Admission Date]], Table14[[#This Row],[Discharge Date]]-Table14[[#This Row],[Admission Date]]) -> 806 | E21: =IF(Table14[[#This Row],[Discharge Date]]="","Still Admitted","Patient Discharged") -> Still Admitted | F21: =IF(WEEKDAY(Table14[[#This Row],[Admission Date]],2)>5,"Weekend","Weekday") -> Weekend | G21: Oncology | H21: 32 | I21: {=_xlfn.IFS(Table14[[#This Row],[Age]]<18,"Children",Table14[[#This Row],[Age]]<50,"Adult",Table14[[#This Row],[Age]]>=50,"Elderly")} -> Adult | J21: Female | K21: 13410 | L21: {=_xlfn.IFS(Table14[[#This Row],[Treatment Cost]]<50000,"Low Billing",Table14[[#This Row],[Treatment Cost]]<200000,"Moderate Billing",Table14[[#This Row],[Treatment Cost]]>=200000,"High Billing")} -> Low Billing | M21: Pending | N21: =IF(AND(Table14[[#This Row],[Outcome]]="Follow-up",Table14[[#This Row],[Admission Status]]="Patient Discharged"),"High Risk Patient","Low Risk Patient") -> Low Risk Patient | O21: =IFERROR(VLOOKUP(Table14[[#This Row],[Department]],Doctor_Info!A:D,2,FALSE), "") -> Dr. George | P21: =IF(COUNTIF(A:A,Table14[[#This Row],[Patient ID]]>1),"Returning Patient","New Patient") -> New Patient | Q21: =_xlfn.XLOOKUP(Table14[[#This Row],[Department]], Doctor_Info!A:A, Doctor_Info!C:C, "")&"" -> 405 | R21: =TEXT(Table14[[#This Row],[Admission Date]],"ddd") -> Sat | S21: =TEXT(Table14[[#This Row],[Admission Date]],"mmm") -> Feb | T21: =TEXT(Table14[[#This Row],[Admission Date]],"yyyy") -> 2024 | U21: =TEXT(Table14[[#This Row],[Admission Date]],"mmm-yyyy") -> Feb-2024 | V21: =MEDIAN($D$2:$D$484) -> 8
A22: HOSP-121 | B22: 45319 | C22: 45327 | D22: =IF(ISBLANK(Table14[[#This Row],[Discharge Date]]),TODAY()-Table14[[#This Row],[Admission Date]], Table14[[#This Row],[Discharge Date]]-Table14[[#This Row],[Admission Date]]) -> 8 | E22: =IF(Table14[[#This Row],[Discharge Date]]="","Still Admitted","Patient Discharged") -> Patient Discharged | F22: =IF(WEEKDAY(Table14[[#This Row],[Admission Date]],2)>5,"Weekend","Weekday") -> Weekend | G22: Cardiology | H22: 30 | I22: {=_xlfn.IFS(Table14[[#This Row],[Age]]<18,"Children",Table14[[#This Row],[Age]]<50,"Adult",Table14[[#This Row],[Age]]>=50,"Elderly")} -> Adult | J22: Male | K22: 14380 | L22: {=_xlfn.IFS(Table14[[#This Row],[Treatment Cost]]<50000,"Low Billing",Table14[[#This Row],[Treatment Cost]]<200000,"Moderate Billing",Table14[[#This Row],[Treatment Cost]]>=200000,"High Billing")} -> Low Billing | M22: Follow-up | N22: =IF(AND(Table14[[#This Row],[Outcome]]="Follow-up",Table14[[#This Row],[Admission Status]]="Patient Discharged"),"High Risk Patient","Low Risk Patient") -> High Risk Patient | O22: =IFERROR(VLOOKUP(Table14[[#This Row],[Department]],Doctor_Info!A:D,2,FALSE), "") -> Dr. Ada | P22: =IF(COUNTIF(A:A,Table14[[#This Row],[Patient ID]]>1),"Returning Patient","New Patient") -> New Patient | Q22: =_xlfn.XLOOKUP(Table14[[#This Row],[Department]], Doctor_Info!A:A, Doctor_Info!C:C, "")&"" -> 301 | R22: =TEXT(Table14[[#This Row],[Admission Date]],"ddd") -> Sun | S22: =TEXT(Table14[[#This Row],[Admission Date]],"mmm") -> Jan | T22: =TEXT(Table14[[#This Row],[Admission Date]],"yyyy") -> 2024 | U22: =TEXT(Table14[[#This Row],[Admission Date]],"mmm-yyyy") -> Jan-2024 | V22: =MEDIAN($D$2:$D$484) -> 8
A23: HOSP-122 | B23: 45323 | C23: 45324 | D23: =IF(ISBLANK(Table14[[#This Row],[Discharge Date]]),TODAY()-Table14[[#This Row],[Admission Date]], Table14[[#This Row],[Discharge Date]]-Table14[[#This Row],[Admission Date]]) -> 1 | E23: =IF(Table14[[#This Row],[Discharge Date]]="","Still Admitted","Patient Discharged") -> Patient Discharged | F23: =IF(WEEKDAY(Table14[[#This Row],[Admission Date]],2)>5,"Weekend","Weekday") -> Weekday | G23: Emergency Ward | H23: 28 | I23: {=_xlfn.IFS(Table14[[#This Row],[Age]]<18,"Children",Table14[[#This Row],[Age]]<50,"Adult",Table14[[#This Row],[Age]]>=50,"Elderly")} -> Adult | J23: Female | K23: 15350 | L23: {=_xlfn.IFS(Table14[[#This Row],[Treatment Cost]]<50000,"Low Billing",Table14[[#This Row],[Treatment Cost]]<200000,"Moderate Billing",Table14[[#This Row],[Treatment Cost]]>=200000,"High Billing")} -> Low Billing | M23: Recovered | N23: =IF(AND(Table14[[#This Row],[Outcome]]="Follow-up",Table14[[#This Row],[Admission Status]]="Patient Discharged"),"High Risk Patient","Low Risk Patient") -> Low Risk Patient | O23: =IFERROR(VLOOKUP(Table14[[#This Row],[Department]],Doctor_Info!A:D,2,FALSE), "") -> Dr. Kofi | P23: =IF(COUNTIF(A:A,Table14[[#This Row],[Patient ID]]>1),"Returning Patient","New Patient") -> New Patient | Q23: =_xlfn.XLOOKUP(Table14[[#This Row],[Department]], Doctor_Info!A:A, Doctor_Info!C:C, "")&"" -> 102 | R23: =TEXT(Table14[[#This Row],[Admission Date]],"ddd") -> Thu | S23: =TEXT(Table14[[#This Row],[Admission Date]],"mmm") -> Feb | T23: =TEXT(Table14[[#This Row],[Admission Date]],"yyyy") -> 2024 | U23: =TEXT(Table14[[#This Row],[Admission Date]],"mmm-yyyy") -> Feb-2024 | V23: =MEDIAN($D$2:$D$484) -> 8
A24: HOSP-123 | B24: 45325 | C24: 45337 | D24: =IF(ISBLANK(Table14[[#This Row],[Discharge Date]]),TODAY()-Table14[[#This Row],[Admission Date]], Table14[[#This Row],[Discharge Date]]-Table14[[#This Row],[Admission Date]]) -> 12 | E24: =IF(Table14[[#This Row],[Discharge Date]]="","Still Admitted","Patient Discharged") -> Patient Discharged | F24: =IF(WEEKDAY(Table14[[#This Row],[Admission Date]],2)>5,"Weekend","Weekday") -> Weekend | G24: Neurology | H24: 26 | I24: {=_xlfn.IFS(Table14[[#This Row],[Age]]<18,"Children",Table14[[#This Row],[Age]]<50,"Adult",Table14[[#This Row],[Age]]>=50,"Elderly")} -> Adult | J24: Male | K24: 16320 | L24: {=_xlfn.IFS(Table14[[#This Row],[Treatment Cost]]<50000,"Low Billing",Table14[[#This Row],[Treatment Cost]]<200000,"Moderate Billing",Table14[[#This Row],[Treatment Cost]]>=200000,"High Billing")} -> Low Billing | M24: Follow-up | N24: =IF(AND(Table14[[#This Row],[Outcome]]="Follow-up",Table14[[#This Row],[Admission Status]]="Patient Discharged"),"High Risk Patient","Low Risk Patient") -> High Risk Patient | O24: =IFERROR(VLOOKUP(Table14[[#This Row],[Department]],Doctor_Info!A:D,2,FALSE), "") -> Dr. Temi | P24: =IF(COUNTIF(A:A,Table14[[#This Row],[Patient ID]]>1),"Returning Patient","New Patient") -> New Patient | Q24: =_xlfn.XLOOKUP(Table14[[#This Row],[Department]], Doctor_Info!A:A, Doctor_Info!C:C, "")&"" -> 502 | R24: =TEXT(Table14[[#This Row],[Admission Date]],"ddd") -> Sat | S24: =TEXT(Table14[[#This Row],[Admission Date]],"mmm") -> Feb | T24: =TEXT(Table14[[#This Row],[Admission Date]],"yyyy") -> 2024 | U24: =TEXT(Table14[[#This Row],[Admission Date]],"mmm-yyyy") -> Feb-2024 | V24: =MEDIAN($D$2:$D$484) -> 8
A25: HOSP-124 | B25: 45327 | C25: 45328 | D25: =IF(ISBLANK(Table14[[#This Row],[Discharge Date]]),TODAY()-Table14[[#This Row],[Admission Date]], Table14[[#This Row],[Discharge Date]]-Table14[[#This Row],[Admission Date]]) -> 1 | E25: =IF(Table14[[#This Row],[Discharge Date]]="","Still Admitted","Patient Discharged") -> Patient Discharged | F25: =IF(WEEKDAY(Table14[[#This Row],[Admission Date]],2)>5,"Weekend","Weekday") -> Weekday | G25: Emergency Ward | H25: 24 | I25: {=_xlfn.IFS(Table14[[#This Row],[Age]]<18,"Children",Table14[[#This Row],[Age]]<50,"Adult",Table14[[#This Row],[Age]]>=50,"Elderly")} -> Adult | J25: Female | K25: 17290 | L25: {=_xlfn.IFS(Table14[[#This Row],[Treatment Cost]]<50000,"Low Billing",Table14[[#This Row],[Treatment Cost]]<200000,"Moderate Billing",Table14[[#This Row],[Treatment Cost]]>=200000,"High Billing")} -> Low Billing | M25: Recovered | N25: =IF(AND(Table14[[#This Row],[Outcome]]="Follow-up",Table14[[#This Row],[Admission Status]]="Patient Discharged"),"High Risk Patient","Low Risk Patient") -> Low Risk Patient | O25: =IFERROR(VLOOKUP(Table14[[#This Row],[Department]],Doctor_Info!A:D,2,FALSE), "") -> Dr. Kofi | P25: =IF(COUNTIF(A:A,Table14[[#This Row],[Patient ID]]>1),"Returning Patient","New Patient") -> New Patient | Q25: =_xlfn.XLOOKUP(Table14[[#This Row],[Department]], Doctor_Info!A:A, Doctor_Info!C:C, "")&"" -> 102 | R25: =TEXT(Table14[[#This Row],[Admission Date]],"ddd") -> Mon | S25: =TEXT(Table14[[#This Row],[Admission Date]],"mmm") -> Feb | T25: =TEXT(Table14[[#This Row],[Admission Date]],"yyyy") -> 2024 | U25: =TEXT(Table14[[#This Row],[Admission Date]],"mmm-yyyy") -> Feb-2024 | V25: =MEDIAN($D$2:$D$484) -> 8
A26: HOSP-125 | B26: 45332 | D26: =IF(ISBLANK(Table14[[#This Row],[Discharge Date]]),TODAY()-Table14[[#This Row],[Admission Date]], Table14[[#This Row],[Discharge Date]]-Table14[[#This Row],[Admission Date]]) -> 806 | E26: =IF(Table14[[#This Row],[Discharge Date]]="","Still Admitted","Patient Discharged") -> Still Admitted | F26: =IF(WEEKDAY(Table14[[#This Row],[Admission Date]],2)>5,"Weekend","Weekday") -> Weekend | G26: Oncology | H26: 22 | I26: {=_xlfn.IFS(Table14[[#This Row],[Age]]<18,"Children",Table14[[#This Row],[Age]]<50,"Adult",Table14[[#This Row],[Age]]>=50,"Elderly")} -> Adult | J26: Female | K26: 18260 | L26: {=_xlfn.IFS(Table14[[#This Row],[Treatment Cost]]<50000,"Low Billing",Table14[[#This Row],[Treatment Cost]]<200000,"Moderate Billing",Table14[[#This Row],[Treatment Cost]]>=200000,"High Billing")} -> Low Billing | M26: Pending | N26: =IF(AND(Table14[[#This Row],[Outcome]]="Follow-up",Table14[[#This Row],[Admission Status]]="Patient Discharged"),"High Risk Patient","Low Risk Patient") -> Low Risk Patient | O26: =IFERROR(VLOOKUP(Table14[[#This Row],[Department]],Doctor_Info!A:D,2,FALSE), "") -> Dr. George | P26: =IF(COUNTIF(A:A,Table14[[#This Row],[Patient ID]]>1),"Returning Patient","New Patient") -> New Patient | Q26: =_xlfn.XLOOKUP(Table14[[#This Row],[Department]], Doctor_Info!A:A, Doctor_Info!C:C, "")&"" -> 405 | R26: =TEXT(Table14[[#This Row],[Admission Date]],"ddd") -> Sat | S26: =TEXT(Table14[[#This Row],[Admission Date]],"mmm") -> Feb | T26: =TEXT(Table14[[#This Row],[Admission Date]],"yyyy") -> 2024 | U26: =TEXT(Table14[[#This Row],[Admission Date]],"mmm-yyyy") -> Feb-2024 | V26: =MEDIAN($D$2:$D$484) -> 8
A27: HOSP-126 | B27: 45319 | C27: 45327 | D27: =IF(ISBLANK(Table14[[#This Row],[Discharge Date]]),TODAY()-Table14[[#This Row],[Admission Date]], Table14[[#This Row],[Discharge Date]]-Table14[[#This Row],[Admission Date]]) -> 8 | E27: =IF(Table14[[#This Row],[Discharge Date]]="","Still Admitted","Patient Discharged") -> Patient Discharged | F27: =IF(WEEKDAY(Table14[[#This Row],[Admission Date]],2)>5,"Weekend","Weekday") -> Weekend | G27: Cardiology | H27: 20 | I27: {=_xlfn.IFS(Table14[[#This Row],[Age]]<18,"Children",Table14[[#This Row],[Age]]<50,"Adult",Table14[[#This Row],[Age]]>=50,"Elderly")} -> Adult | J27: Male | K27: 19230 | L27: {=_xlfn.IFS(Table14[[#This Row],[Treatment Cost]]<50000,"Low Billing",Table14[[#This Row],[Treatment Cost]]<200000,"Moderate Billing",Table14[[#This Row],[Treatment Cost]]>=200000,"High Billing")} -> Low Billing | M27: Follow-up | N27: =IF(AND(Table14[[#This Row],[Outcome]]="Follow-up",Table14[[#This Row],[Admission Status]]="Patient Discharged"),"High Risk Patient","Low Risk Patient") -> High Risk Patient | O27: =IFERROR(VLOOKUP(Table14[[#This Row],[Department]],Doctor_Info!A:D,2,FALSE), "") -> Dr. Ada | P27: =IF(COUNTIF(A:A,Table14[[#This Row],[Patient ID]]>1),"Returning Patient","New Patient") -> New Patient | Q27: =_xlfn.XLOOKUP(Table14[[#This Row],[Department]], Doctor_Info!A:A, Doctor_Info!C:C, "")&"" -> 301 | R27: =TEXT(Table14[[#This Row],[Admission Date]],"ddd") -> Sun | S27: =TEXT(Table14[[#This Row],[Admission Date]],"mmm") -> Jan | T27: =TEXT(Table14[[#This Row],[Admission Date]],"yyyy") -> 2024 | U27: =TEXT(Table14[[#This Row],[Admission Date]],"mmm-yyyy") -> Jan-2024 | V27: =MEDIAN($D$2:$D$484) -> 8
A28: HOSP-127 | B28: 45323 | C28: 45324 | D28: =IF(ISBLANK(Table14[[#This Row],[Discharge Date]]),TODAY()-Table14[[#This Row],[Admission Date]], Table14[[#This Row],[Discharge Date]]-Table14[[#This Row],[Admission Date]]) -> 1 | E28: =IF(Table14[[#This Row],[Discharge Date]]="","Still Admitted","Patient Discharged") -> Patient Discharged | F28: =IF(WEEKDAY(Table14[[#This Row],[Admission Date]],2)>5,"Weekend","Weekday") -> Weekday | G28: Emergency Ward | H28: 18 | I28: {=_xlfn.IFS(Table14[[#This Row],[Age]]<18,"Children",Table14[[#This Row],[Age]]<50,"Adult",Table14[[#This Row],[Age]]>=50,"Elderly")} -> Adult | J28: Female | K28: 20200 | L28: {=_xlfn.IFS(Table14[[#This Row],[Treatment Cost]]<50000,"Low Billing",Table14[[#This Row],[Treatment Cost]]<200000,"Moderate Billing",Table14[[#This Row],[Treatment Cost]]>=200000,"High Billing")} -> Low Billing | M28: Recovered | N28: =IF(AND(Table14[[#This Row],[Outcome]]="Follow-up",Table14[[#This Row],[Admission Status]]="Patient Discharged"),"High Risk Patient","Low Risk Patient") -> Low Risk Patient | O28: =IFERROR(VLOOKUP(Table14[[#This Row],[Department]],Doctor_Info!A:D,2,FALSE), "") -> Dr. Kofi | P28: =IF(COUNTIF(A:A,Table14[[#This Row],[Patient ID]]>1),"Returning Patient","New Patient") -> New Patient | Q28: =_xlfn.XLOOKUP(Table14[[#This Row],[Department]], Doctor_Info!A:A, Doctor_Info!C:C, "")&"" -> 102 | R28: =TEXT(Table14[[#This Row],[Admission Date]],"ddd") -> Thu | S28: =TEXT(Table14[[#This Row],[Admission Date]],"mmm") -> Feb | T28: =TEXT(Table14[[#This Row],[Admission Date]],"yyyy") -> 2024 | U28: =TEXT(Table14[[#This Row],[Admission Date]],"mmm-yyyy") -> Feb-2024 | V28: =MEDIAN($D$2:$D$484) -> 8
A29: HOSP-128 | B29: 45325 | C29: 45337 | D29: =IF(ISBLANK(Table14[[#This Row],[Discharge Date]]),TODAY()-Table14[[#This Row],[Admission Date]], Table14[[#This Row],[Discharge Date]]-Table14[[#This Row],[Admission Date]]) -> 12 | E29: =IF(Table14[[#This Row],[Discharge Date]]="","Still Admitted","Patient Discharged") -> Patient Discharged | F29: =IF(WEEKDAY(Table14[[#This Row],[Admission Date]],2)>5,"Weekend","Weekday") -> Weekend | G29: Neurology | H29: 16 | I29: {=_xlfn.IFS(Table14[[#This Row],[Age]]<18,"Children",Table14[[#This Row],[Age]]<50,"Adult",Table14[[#This Row],[Age]]>=50,"Elderly")} -> Children | J29: Male | K29: 21170 | L29: {=_xlfn.IFS(Table14[[#This Row],[Treatment Cost]]<50000,"Low Billing",Table14[[#This Row],[Treatment Cost]]<200000,"Moderate Billing",Table14[[#This Row],[Treatment Cost]]>=200000,"High Billing")} -> Low Billing | M29: Follow-up | N29: =IF(AND(Table14[[#This Row],[Outcome]]="Follow-up",Table14[[#This Row],[Admission Status]]="Patient Discharged"),"High Risk Patient","Low Risk Patient") -> High Risk Patient | O29: =IFERROR(VLOOKUP(Table14[[#This Row],[Department]],Doctor_Info!A:D,2,FALSE), "") -> Dr. Temi | P29: =IF(COUNTIF(A:A,Table14[[#This Row],[Patient ID]]>1),"Returning Patient","New Patient") -> New Patient | Q29: =_xlfn.XLOOKUP(Table14[[#This Row],[Department]], Doctor_Info!A:A, Doctor_Info!C:C, "")&"" -> 502 | R29: =TEXT(Table14[[#This Row],[Admission Date]],"ddd") -> Sat | S29: =TEXT(Table14[[#This Row],[Admission Date]],"mmm") -> Feb | T29: =TEXT(Table14[[#This Row],[Admission Date]],"yyyy") -> 2024 | U29: =TEXT(Table14[[#This Row],[Admission Date]],"mmm-yyyy") -> Feb-2024 | V29: =MEDIAN($D$2:$D$484) -> 8
A30: HOSP-129 | B30: 45327 | C30: 45328 | D30: =IF(ISBLANK(Table14[[#This Row],[Discharge Date]]),TODAY()-Table14[[#This Row],[Admission Date]], Table14[[#This Row],[Discharge Date]]-Table14[[#This Row],[Admission Date]]) -> 1 | E30: =IF(Table14[[#This Row],[Discharge Date]]="","Still Admitted","Patient Discharged") -> Patient Discharged | F30: =IF(WEEKDAY(Table14[[#This Row],[Admission Date]],2)>5,"Weekend","Weekday") -> Weekday | G30: Emergency Ward | H30: 14 | I30: {=_xlfn.IFS(Table14[[#This Row],[Age]]<18,"Children",Table14[[#This Row],[Age]]<50,"Adult",Table14[[#This Row],[Age]]>=50,"Elderly")} -> Children | J30: Female | K30: 22140 | L30: {=_xlfn.IFS(Table14[[#This Row],[Treatment Cost]]<50000,"Low Billing",Table14[[#This Row],[Treatment Cost]]<200000,"Moderate Billing",Table14[[#This Row],[Treatment Cost]]>=200000,"High Billing")} -> Low Billing | M30: Recovered | N30: =IF(AND(Table14[[#This Row],[Outcome]]="Follow-up",Table14[[#This Row],[Admission Status]]="Patient Discharged"),"High Risk Patient","Low Risk Patient") -> Low Risk Patient | O30: =IFERROR(VLOOKUP(Table14[[#This Row],[Department]],Doctor_Info!A:D,2,FALSE), "") -> Dr. Kofi | P30: =IF(COUNTIF(A:A,Table14[[#This Row],[Patient ID]]>1),"Returning Patient","New Patient") -> New Patient | Q30: =_xlfn.XLOOKUP(Table14[[#This Row],[Department]], Doctor_Info!A:A, Doctor_Info!C:C, "")&"" -> 102 | R30: =TEXT(Table14[[#This Row],[Admission Date]],"ddd") -> Mon | S30: =TEXT(Table14[[#This Row],[Admission Date]],"mmm") -> Feb | T30: =TEXT(Table14[[#This Row],[Admission Date]],"yyyy") -> 2024 | U30: =TEXT(Table14[[#This Row],[Admission Date]],"mmm-yyyy") -> Feb-2024 | V30: =MEDIAN($D$2:$D$484) -> 8
A31: HOSP-130 | B31: 45332 | D31: =IF(ISBLANK(Table14[[#This Row],[Discharge Date]]),TODAY()-Table14[[#This Row],[Admission Date]], Table14[[#This Row],[Discharge Date]]-Table14[[#This Row],[Admission Date]]) -> 806 | E31: =IF(Table14[[#This Row],[Discharge Date]]="","Still Admitted","Patient Discharged") -> Still Admitted | F31: =IF(WEEKDAY(Table14[[#This Row],[Admission Date]],2)>5,"Weekend","Weekday") -> Weekend | G31: Oncology | H31: 12 | I31: {=_xlfn.IFS(Table14[[#This Row],[Age]]<18,"Children",Table14[[#This Row],[Age]]<50,"Adult",Table14[[#This Row],[Age]]>=50,"Elderly")} -> Children | J31: Female | K31: 23110 | L31: {=_xlfn.IFS(Table14[[#This Row],[Treatment Cost]]<50000,"Low Billing",Table14[[#This Row],[Treatment Cost]]<200000,"Moderate Billing",Table14[[#This Row],[Treatment Cost]]>=200000,"High Billing")} -> Low Billing | M31: Pending | N31: =IF(AND(Table14[[#This Row],[Outcome]]="Follow-up",Table14[[#This Row],[Admission Status]]="Patient Discharged"),"High Risk Patient","Low Risk Patient") -> Low Risk Patient | O31: =IFERROR(VLOOKUP(Table14[[#This Row],[Department]],Doctor_Info!A:D,2,FALSE), "") -> Dr. George | P31: =IF(COUNTIF(A:A,Table14[[#This Row],[Patient ID]]>1),"Returning Patient","New Patient") -> New Patient | Q31: =_xlfn.XLOOKUP(Table14[[#This Row],[Department]], Doctor_Info!A:A, Doctor_Info!C:C, "")&"" -> 405 | R31: =TEXT(Table14[[#This Row],[Admission Date]],"ddd") -> Sat | S31: =TEXT(Table14[[#This Row],[Admission Date]],"mmm") -> Feb | T31: =TEXT(Table14[[#This Row],[Admission Date]],"yyyy") -> 2024 | U31: =TEXT(Table14[[#This Row],[Admission Date]],"mmm-yyyy") -> Feb-2024 | V31: =MEDIAN($D$2:$D$484) -> 8
A32: HOSP-131 | B32: 45319 | C32: 45327 | D32: =IF(ISBLANK(Table14[[#This Row],[Discharge Date]]),TODAY()-Table14[[#This Row],[Admission Date]], Table14[[#This Row],[Discharge Date]]-Table14[[#This Row],[Admission Date]]) -> 8 | E32: =IF(Table14[[#This Row],[Discharge Date]]="","Still Admitted","Patient Discharged") -> Patient Discharged | F32: =IF(WEEKDAY(Table14[[#This Row],[Admission Date]],2)>5,"Weekend","Weekday") -> Weekend | G32: Cardiology | H32: 10 | I32: {=_xlfn.IFS(Table14[[#This Row],[Age]]<18,"Children",Table14[[#This Row],[Age]]<50,"Adult",Table14[[#This Row],[Age]]>=50,"Elderly")} -> Children | J32: Male | K32: 24080 | L32: {=_xlfn.IFS(Table14[[#This Row],[Treatment Cost]]<50000,"Low Billing",Table14[[#This Row],[Treatment Cost]]<200000,"Moderate Billing",Table14[[#This Row],[Treatment Cost]]>=200000,"High Billing")} -> Low Billing | M32: Follow-up | N32: =IF(AND(Table14[[#This Row],[Outcome]]="Follow-up",Table14[[#This Row],[Admission Status]]="Patient Discharged"),"High Risk Patient","Low Risk Patient") -> High Risk Patient | O32: =IFERROR(VLOOKUP(Table14[[#This Row],[Department]],Doctor_Info!A:D,2,FALSE), "") -> Dr. Ada | P32: =IF(COUNTIF(A:A,Table14[[#This Row],[Patient ID]]>1),"Returning Patient","New Patient") -> New Patient | Q32: =_xlfn.XLOOKUP(Table14[[#This Row],[Department]], Doctor_Info!A:A, Doctor_Info!C:C, "")&"" -> 301 | R32: =TEXT(Table14[[#This Row],[Admission Date]],"ddd") -> Sun | S32: =TEXT(Table14[[#This Row],[Admission Date]],"mmm") -> Jan | T32: =TEXT(Table14[[#This Row],[Admission Date]],"yyyy") -> 2024 | U32: =TEXT(Table14[[#This Row],[Admission Date]],"mmm-yyyy") -> Jan-2024 | V32: =MEDIAN($D$2:$D$484) -> 8
A33: HOSP-132 | B33: 45323 | C33: 45324 | D33: =IF(ISBLANK(Table14[[#This Row],[Discharge Date]]),TODAY()-Table14[[#This Row],[Admission Date]], Table14[[#This Row],[Discharge Date]]-Table14[[#This Row],[Admission Date]]) -> 1 | E33: =IF(Table14[[#This Row],[Discharge Date]]="","Still Admitted","Patient Discharged") -> Patient Discharged | F33: =IF(WEEKDAY(Table14[[#This Row],[Admission Date]],2)>5,"Weekend","Weekday") -> Weekday | G33: Emergency Ward | H33: 8 | I33: {=_xlfn.IFS(Table14[[#This Row],[Age]]<18,"Children",Table14[[#This Row],[Age]]<50,"Adult",Table14[[#This Row],[Age]]>=50,"Elderly")} -> Children | J33: Female | K33: 25050 | L33: {=_xlfn.IFS(Table14[[#This Row],[Treatment Cost]]<50000,"Low Billing",Table14[[#This Row],[Treatment Cost]]<200000,"Moderate Billing",Table14[[#This Row],[Treatment Cost]]>=200000,"High Billing")} -> Low Billing | M33: Recovered | N33: =IF(AND(Table14[[#This Row],[Outcome]]="Follow-up",Table14[[#This Row],[Admission Status]]="Patient Discharged"),"High Risk Patient","Low Risk Patient") -> Low Risk Patient | O33: =IFERROR(VLOOKUP(Table14[[#This Row],[Department]],Doctor_Info!A:D,2,FALSE), "") -> Dr. Kofi | P33: =IF(COUNTIF(A:A,Table14[[#This Row],[Patient ID]]>1),"Returning Patient","New Patient") -> New Patient | Q33: =_xlfn.XLOOKUP(Table14[[#This Row],[Department]], Doctor_Info!A:A, Doctor_Info!C:C, "")&"" -> 102 | R33: =TEXT(Table14[[#This Row],[Admission Date]],"ddd") -> Thu | S33: =TEXT(Table14[[#This Row],[Admission Date]],"mmm") -> Feb | T33: =TEXT(Table14[[#This Row],[Admission Date]],"yyyy") -> 2024 | U33: =TEXT(Table14[[#This Row],[Admission Date]],"mmm-yyyy") -> Feb-2024 | V33: =MEDIAN($D$2:$D$484) -> 8
A34: HOSP-133 | B34: 45325 | C34: 45337 | D34: =IF(ISBLANK(Table14[[#This Row],[Discharge Date]]),TODAY()-Table14[[#This Row],[Admission Date]], Table14[[#This Row],[Discharge Date]]-Table14[[#This Row],[Admission Date]]) -> 12 | E34: =IF(Table14[[#This Row],[Discharge Date]]="","Still Admitted","Patient Discharged") -> Patient Discharged | F34: =IF(WEEKDAY(Table14[[#This Row],[Admission Date]],2)>5,"Weekend","Weekday") -> Weekend | G34: Neurology | H34: 6 | I34: {=_xlfn.IFS(Table14[[#This Row],[Age]]<18,"Children",Table14[[#This Row],[Age]]<50,"Adult",Table14[[#This Row],[Age]]>=50,"Elderly")} -> Children | J34: Male | K34: 26020 | L34: {=_xlfn.IFS(Table14[[#This Row],[Treatment Cost]]<50000,"Low Billing",Table14[[#This Row],[Treatment Cost]]<200000,"Moderate Billing",Table14[[#This Row],[Treatment Cost]]>=200000,"High Billing")} -> Low Billing | M34: Follow-up | N34: =IF(AND(Table14[[#This Row],[Outcome]]="Follow-up",Table14[[#This Row],[Admission Status]]="Patient Discharged"),"High Risk Patient","Low Risk Patient") -> High Risk Patient | O34: =IFERROR(VLOOKUP(Table14[[#This Row],[Department]],Doctor_Info!A:D,2,FALSE), "") -> Dr. Temi | P34: =IF(COUNTIF(A:A,Table14[[#This Row],[Patient ID]]>1),"Returning Patient","New Patient") -> New Patient | Q34: =_xlfn.XLOOKUP(Table14[[#This Row],[Department]], Doctor_Info!A:A, Doctor_Info!C:C, "")&"" -> 502 | R34: =TEXT(Table14[[#This Row],[Admission Date]],"ddd") -> Sat | S34: =TEXT(Table14[[#This Row],[Admission Date]],"mmm") -> Feb | T34: =TEXT(Table14[[#This Row],[Admission Date]],"yyyy") -> 2024 | U34: =TEXT(Table14[[#This Row],[Admission Date]],"mmm-yyyy") -> Feb-2024 | V34: =MEDIAN($D$2:$D$484) -> 8
